Workbook
Name _9_Inches: #REF!

Sheet SALES__DATA
A1: Date Of Sales | B1: Customer Name | C1: Product Type | D1: Qty Sold | E1: Rate | F1: Amount | G1: Bad Debt | H1: Revenue | I1: DAILY | J1: MONTHLY | K1: ANUALLY
A2: 44569 | B2: DAD SEMILORE | C2: 6 Inches | D2: 224 | E2: 250 | F2: =D2*E2 -> 56000 | H2: 56000 | I2: SATURDAY | J2: JANUARY | K2: 2022
A3: 44573 | B3: MR&MRS OMOLERE | C3: 7 Inches | D3: 300 | E3: 260 | F3: =D3*E3 -> 78000 | H3: 78000 | I3: WEDNESDAY | J3: JANUARY | K3: 2022
A4: 44590 | B4: ORIYOMI | C4: 9 Inches | D4: 250 | E4: 295 | F4: =D4*E4 -> 73750 | H4: 73750 | I4: SATURDAY | J4: JANUARY | K4: 2022
A5: 44592 | B5: ORIYOMI | C5: 6 Inches | D5: 500 | E5: 265 | F5: =D5*E5 -> 132500 | H5: 132500 | I5: MONDAY | J5: JANUARY | K5: 2022
A6: 44593 | B6: CSTM@OKO-OPE | C6: 6 Inches | D6: 400 | E6: 260 | F6: =D6*E6 -> 104000 | G6: 1000 | H6: 103000 | I6: TUESDAY | J6: FEBRUARY | K6: 2022
A7: 44596 | B7: MR&MRS OMOLERE | C7: 7 Inches | D7: 150 | E7: 275 | F7: =D7*E7 -> 41250 | G7: 250 | H7: 41000 | I7: FRIDAY | J7: FEBRUARY | K7: 2022
A8: 44597 | B8: Nearby CSTM@OKO-OPE | C8: 6 Inches | D8: 12 | E8: 270 | F8: =D8*E8 -> 3240 | G8: 140 | H8: 3100 | I8: SATURDAY | J8: FEBRUARY | K8: 2022
A9: 44600 | B9: IYA ADURA | C9: 6 Inches | D9: 150 | E9: 260 | F9: =D9*E9 -> 39000 | H9: 39000 | I9: TUESDAY | J9: FEBRUARY | K9: 2022
A10: 44607 | B10: BABA IBEJI BRICK-LAYER | C10: 6 Inches | D10: 25 | E10: 250 | F10: =D10*E10 -> 6250 | H10: 6250 | I10: TUESDAY | J10: FEBRUARY | K10: 2022
A11: 44608 | B11: BABA SAMSON | C11: 7 Inches | D11: 400 | E11: 280 | F11: =D11*E11 -> 112000 | H11: 112000 | I11: WEDNESDAY | J11: FEBRUARY | K11: 2022
A12: 44611 | B12: SERIKI | C12: 6 Inches | D12: 4 | E12: 250 | F12: =D12*E12 -> 1000 | H12: 1000 | I12: SATURDAY | J12: FEBRUARY | K12: 2022
A13: 44616 | B13: BABA IBEJI BRICK-LAYER | C13: 9 Inches | D13: 130 | E13: 300 | F13: =D13*E13 -> 39000 | H13: 39000 | I13: THURSDAY | J13: FEBRUARY | K13: 2022
A14: 44620 | B14: CHURCH ORIOKE | C14: 9 Inches | D14: 12 | E14: 300 | F14: =D14*E14 -> 3600 | H14: 3600 | I14: MONDAY | J14: FEBRUARY | K14: 2022
A15: 44623 | B15: CORNERPIECE | C15: 6 Inches | D15: 2 | E15: 300 | F15: =D15*E15 -> 600 | H15: 600 | I15: THURSDAY | J15: MARCH | K15: 2022
A16: 44625 | B16: BABA SAMSON | C16: 7 Inches | D16: 50 | E16: 330 | F16: =D16*E16 -> 16500 | H16: 16500 | I16: SATURDAY | J16: MARCH | K16: 2022
A17: 44632 | B17: BABA SAMSON | C17: 7 Inches | D17: 50 | E17: 330 | F17: =D17*E17 -> 16500 | H17: 16500 | I17: SATURDAY | J17: MARCH | K17: 2022
A18: 44638 | B18: MR&MRS OMOLERE | C18: 7 Inches | D18: 500 | E18: 320 | F18: =D18*E18 -> 160000 | H18: 160000 | I18: FRIDAY | J18: MARCH | K18: 2022
A19: 44648 | B19: MR&MRS OMOLERE | C19: 7 Inches | D19: 200 | E19: 320 | F19: =D19*E19 -> 64000 | H19: 64000 | I19: MONDAY | J19: MARCH | K19: 2022
A20: 44652 | B20: MR&MRS OMOLERE | C20: 7 Inches | D20: 200 | E20: 320 | F20: =D20*E20 -> 64000 | H20: 64000 | I20: FRIDAY | J20: APRIL | K20: 2022
... A24: 44674 | B24: ALHJ ONAARA | C24: 7 Inches | D24: 60 | E24: 330 | F24: =D24*E24 -> 19800 | H24: 19800 | I24: SATURDAY | J24: APRIL | K24: 2022
A25: 44690 | B25: OLORI | C25: 6 Inches | D25: 16 | E25: 300 | F25: =D25*E25 -> 4800 | G25: 4300 | H25: 500 | I25: MONDAY | J25: MAY | K25: 2022
A26: 44693 | B26: MR&MRS OMOLERE | C26: 7 Inches | D26: 60 | E26: 320 | F26: =D26*E26 -> 19200 | H26: 19200 | I26: THURSDAY | J26: MAY | K26: 2022
A27: 44711 | B27: MR&MRS OMOLERE | C27: 7 Inches | D27: 250 | E27: 320 | F27: =D27*E27 -> 80000 | H27: 80000 | I27: MONDAY | J27: MAY | K27: 2022
A28: 44712 | B28: DAD PRAISE REFERRAL 1 | C28: 6 Inches | D28: 50 | E28: 300 | F28: =D28*E28 -> 15000 | H28: 15000 | I28: TUESDAY | J28: MAY | K28: 2022
A29: 44715 | B29: OGA SANMI | C29: 9 Inches | D29: 400 | E29: 320 | F29: =D29*E29 -> 128000 | H29: 128000 | I29: FRIDAY | J29: JUNE | K29: 2022
A30: 44721 | B30: MR&MRS OMOLERE | C30: 7 Inches | D30: 150 | E30: 320 | F30: =D30*E30 -> 48000 | H30: 48000 | I30: THURSDAY | J30: JUNE | K30: 2022
A31: 44723 | B31: SUPRISE MUMMY | C31: 6 Inches | D31: 16 | E31: 300 | F31: =D31*E31 -> 4800 | H31: 4800 | I31: SATURDAY | J31: JUNE | K31: 2022
A32: 44725 | B32: DAD PRAISE REFERRAL 1 | C32: 6 Inches | D32: 80 | E32: 300 | F32: =D32*E32 -> 24000 | H32: 24000 | I32: MONDAY | J32: JUNE | K32: 2022
A33: 44726 | B33: DAD PRAISE REFERRAL 1 | C33: 6 Inches | D33: 40 | E33: 300 | F33: =D33*E33 -> 12000 | H33: 12000 | I33: TUESDAY | J33: JUNE | K33: 2022
A34: 44730 | B34: DAD PRAISE REFERRAL 1 | C34: 6 Inches | D34: 20 | E34: 300 | F34: =D34*E34 -> 6000 | H34: 6000 | I34: SATURDAY | J34: JUNE | K34: 2022
A35: 44758 | B35: CSTM@OKO-OPE | C35: 6 Inches | D35: 500 | E35: 330 | F35: =D35*E35 -> 165000 | G35: 5000 | H35: 160000 | I35: SATURDAY | J35: JULY | K35: 2022
A36: 44769 | B36: ADEBISI SCH. | C36: 6 Inches | D36: 100 | E36: 300 | F36: =D36*E36 -> 30000 | H36: 30000 | I36: WEDNESDAY | J36: JULY | K36: 2022
A37: 44792 | B37: ENG. WAHEED | C37: 9 Inches | D37: 3800 | E37: 350 | F37: =D37*E37 -> 1330000 | H37: 1330000 | I37: FRIDAY | J37: AUGUST | K37: 2022
A38: 44792 | B38: ENG. WAHEED | C38: 6 Inches | D38: 800 | E38: 330 | F38: =D38*E38 -> 264000 | H38: 264000 | I38: FRIDAY | J38: AUGUST | K38: 2022
A39: 44813 | B39: ADEBISI SCH. | C39: 6 Inches | D39: 100 | E39: 300 | F39: =D39*E39 -> 30000 | H39: 30000 | I39: FRIDAY | J39: SEPTEMBER | K39: 2022
A40: 44814 | B40: BRICKLAYER CONERPIEC 1 | C40: 6 Inches | D40: 16 | E40: 330 | F40: =D40*E40 -> 5280 | H40: 5280 | I40: SATURDAY | J40: SEPTEMBER | K40: 2022
A41: 44816 | B41: ENG. WAHEED | C41: 9 Inches | D41: 50 | E41: 350 | F41: =D41*E41 -> 17500 | G41: 17500 | H41: 0 | I41: MONDAY | J41: SEPTEMBER | K41: 2022
A42: 44816 | B42: ENG. WAHEED | C42: 7 Inches | D42: 220 | E42: 340 | F42: =D42*E42 -> 74800 | H42: 74800 | I42: MONDAY | J42: SEPTEMBER | K42: 2022
A43: 44818 | B43: ENG. WAHEED | C43: 6 Inches | D43: 450 | E43: 330 | F43: =D43*E43 -> 148500 | H43: 148500 | I43: WEDNESDAY | J43: SEPTEMBER | K43: 2022
...

Sheet PRODUCTION_DATA
A1: Date | B1: 6 Inches Qty | C1: 7 Inches Qty | D1: 9 Inches Qty | E1: Total Qty Produced | F1: Total Qty Sold | G1: Tons Of Sand | H1: Bags of Cement | I1: Bag Produced | J1: Ltr. Of Fuel | K1: Sand Cost | L1: Cement Cost | M1: Operators' Payment | N1: Fuel Cost | O1: Maintenance | P1: Delivery Cost | Q1: Total Revenue | R1: Total Cost | S1: Total Profit | T1: Bad Debt | U1: MONTHLY | V1: ANUALLY
A2: 44531 | B2: 1020 | C2: 500 | D2: 336 | E2: 1856 | G2: 30 | H2: 35 | I2: 35 | J2: 25 | K2: 90000 | L2: 140000 | M2: 42000 | N2: 4125 | R2: 276125 | S2: -276125 | U2: DEC | V2: 2021
A3: 44562 | F3: 1274 | P3: 63700 | Q3: 340250 | R3: 63700 | S3: 276550 | U3: JAN | V3: 2022
A4: 44593 | B4: 900 | C4: 1250 | D4: 210 | E4: 2360 | F4: 1283 | G4: 48 | H4: 45 | I4: 45 | J4: 24 | K4: 147500 | L4: 189000 | M4: 67500 | N4: 4000 | P4: 64150 | Q4: 347950 | R4: 472150 | S4: -124200 | T4: 1390 | U4: FEB | V4: 2022
A5: 44621 | B5: 440 | C5: 96 | D5: 252 | E5: 788 | F5: 802 | G5: 20 | H5: 29 | I5: 16 | J5: 24 | K5: 70000 | L5: 119400 | M5: 22400 | N5: 4000 | P5: 40100 | Q5: 257600 | R5: 255900 | S5: 1700 | U5: MAR | V5: 2022
A6: 44652 | C6: 700 | D6: 798 | E6: 1498 | F6: 1560 | G6: 30 | H6: 22 | I6: 33 | J6: 27 | K6: 120000 | L6: 90000 | M6: 48000 | N6: 4400 | P6: 78000 | Q6: 521800 | R6: 340400 | S6: 181400 | U6: APR | V6: 2022
A7: 44682 | C7: 546 | E7: 546 | F7: 376 | G7: 10 | H7: 10 | I7: 11 | J7: 12 | K7: 40000 | L7: 40000 | M7: 15000 | N7: 2000 | P7: 18800 | Q7: 114700 | R7: 115800 | S7: -1100 | T7: 4300 | U7: MAY | V7: 2022
A8: 44713 | D8: 645 | E8: 645 | F8: 706 | G8: 30 | H8: 20 | I8: 15 | J8: 12 | K8: 120000 | L8: 82000 | M8: 22500 | N8: 2000 | P8: 35300 | Q8: 222800 | R8: 261800 | S8: -39000 | U8: JUN | V8: 2022
A9: 44743 | B9: 780 | E9: 780 | F9: 600 | G9: 10 | H9: 12 | I9: 13 | J9: 12 | K9: 50000 | L9: 45700 | M9: 15000 | N9: 2000 | P9: 30000 | Q9: 190000 | R9: 142700 | S9: 47300 | T9: 5000 | U9: JUL | V9: 2022
A10: 44774 | B10: 569 | D10: 3226 | E10: 3795 | F10: 4600 | G10: 100 | H10: 86 | I10: 86 | J10: 61 | K10: 500000 | L10: 348300 | M10: 129000 | N10: 10000 | O10: 77900 | P10: 230000 | Q10: 1594000 | R10: 1295200 | S10: 298800 | U10: AUG | V10: 2022
A11: 44805 | B11: 1320 | C11: 450 | D11: 516 | E11: 2286 | F11: 954 | G11: 20 | H11: 53 | I11: 48 | J11: 48 | K11: 100000 | L11: 214650 | M11: 72000 | N11: 8000 | O11: 2000 | P11: 47700 | Q11: 297980 | R11: 444350 | S11: -146370 | T11: 18200 | U11: SEP | V11: 2022
A12: 44835 | B12: 1740 | C12: 400 | D12: 1634 | E12: 3774 | F12: 3460 | G12: 90 | H12: 70 | I12: 75 | J12: 48 | K12: 435000 | L12: 283500 | M12: 112500 | N12: 8000 | O12: 5500 | P12: 173000 | Q12: 1176300 | R12: 1017500 | S12: 158800 | T12: 48000 | U12: OCT | V12: 2022
A13: 44866 | D13: 430 | E13: 430 | F13: 1150 | G13: 10 | H13: 10 | I13: 10 | J13: 24 | K13: 50000 | L13: 40500 | M13: 15000 | N13: 4000 | O13: 5000 | P13: 57500 | Q13: 425000 | R13: 172000 | S13: 253000 | U13: NOV | V13: 2022
A14: 44896 | B14: 840 | D14: 817 | E14: 1657 | F14: 1534 | G14: 60 | H14: 33 | I14: 33 | J14: 30 | K14: 225000 | L14: 155100 | M14: 49500 | N14: 5000 | P14: 76700 | Q14: 580000 | R14: 511300 | S14: 68700 | T14: 230 | U14: DEC | V14: 2022
A15: 44927 | B15: 480 | D15: 344 | E15: 824 | F15: 950 | G15: 18 | H15: 18 | I15: 16 | J15: 20 | K15: 87500 | L15: 86400 | M15: 24000 | N15: 4000 | P15: 57000 | Q15: 351320 | R15: 258900 | S15: 92420 | U15: JAN | V15: 2023
A16: 44958 | V16: 2023
A17: 44986 | B17: 420 | D17: 1591 | E17: 2011 | F17: 1616 | G17: 38 | H17: 44 | I17: 44 | J17: 39 | K17: 187500 | L17: 209000 | M17: 66000 | N17: 7500 | O17: 2000 | P17: 96960 | Q17: 644100 | R17: 568960 | S17: 75140 | T17: 100 | U17: MAR | V17: 2023
A18: 45017 | B18: 900 | C18: 2500 | D18: 215 | E18: 3615 | F18: 3381 | G18: 72 | H18: 70 | I18: 70 | J18: 56 | K18: 362500 | L18: 328900 | M18: 120000 | N18: 11030 | O18: 2000 | P18: 52860 | Q18: 1015940 | R18: 877290 | S18: 138650 | T18: 50000 | U18: APR | V18: 2023
A19: 45047 | B19: 303 | C19: 201 | E19: 504 | F19: 1642 | G19: 8 | H19: 7 | I19: 6 | J19: 8 | K19: 37500 | L19: 32900 | M19: 9000 | N19: 1500 | P19: 98520 | Q19: 584200 | R19: 179420 | S19: 404780 | U19: MAY | V19: 2023
A20: 45078 | D20: 760 | E20: 760 | F20: 870 | G20: 42 | H20: 20 | I20: 20 | J20: 8 | K20: 212500 | L20: 145500 | M20: 30000 | N20: 2000 | P20: 52200 | Q20: 343200 | R20: 442200 | S20: -99000 | U20: JUN | V20: 2023
A21: 45108 | D21: 903 | E21: 903 | F21: 470 | G21: 28 | H21: 27 | I21: 21 | J21: 14 | K21: 137500 | L21: 135300 | M21: 32000 | N21: 7470 | O21: 20200 | P21: 28200 | Q21: 181500 | R21: 360670 | S21: -179170 | U21: JUL | V21: 2023
A22: 45139 | B22: 480 | D22: 560 | E22: 1040 | F22: 440 | G22: 25 | H22: 16 | I22: 21 | J22: 6 | K22: 125000 | L22: 87200 | M22: 33500 | N22: 3480 | P22: 26400 | Q22: 182200 | R22: 275580 | S22: -93380 | T22: 1000 | U22: AUG | V22: 2023
A23: 45170 | B23: 660 | D23: 1419 | E23: 2079 | F23: 1928 | G23: 48 | H23: 43 | I23: 44 | J23: 22 | K23: 237500 | L23: 230050 | M23: 74800 | N23: 12800 | O23: 20000 | P23: 115680 | Q23: 841200 | R23: 690830 | S23: 150370 | U23: SEP | V23: 2023
A24: 45200 | B24: 1920 | D24: 860 | E24: 2780 | F24: 2838 | G24: 65 | H24: 53 | I24: 52 | J24: 26 | K24: 360000 | L24: 283550 | M24: 138600 | N24: 15600 | O24: 3000 | P24: 170280 | Q24: 1255440 | R24: 971030 | S24: 284410 | T24: 2150 | U24: OCT | V24: 2023
A25: 45231 | B25: 1140 | E25: 1140 | F25: 982 | G25: 18 | H25: 18 | I25: 19 | J25: 8 | K25: 100000 | L25: 98100 | M25: 32300 | N25: 4800 | O25: 1500 | P25: 58920 | Q25: 446900 | R25: 295620 | S25: 151280 | U25: NOV | V25: 2023
A26: 45261 | B26: 840 | D26: 817 | E26: 1657 | F26: 1505 | G26: 50 | H26: 33 | I26: 33 | J26: 26 | K26: 300000 | L26: 179850 | M26: 56100 | N26: 16000 | O26: 4000 | P26: 90300 | Q26: 710450 | R26: 646250 | S26: 64200 | U26: DEC | V26: 2023
A27: 45292 | F27: 720 | G27: 8 | K27: 45000 | O27: 10000 | P27: 50400 | Q27: 294000 | R27: 105400 | S27: 188600 | U27: JAN | V27: 2024
A28: 45323 | B28: 1560 | C28: 20 | D28: 430 | E28: 2010 | F28: 2020 | G28: 45 | H28: 40 | I28: 40 | J28: 16 | K28: 270000 | L28: 435800 | M28: 78000 | N28: 10000 | P28: 141400 | Q28: 1120000 | R28: 935200 | S28: 184800 | U28: FEB | V28: 2024
A29: 45352 | F29: 347 | G29: 10 | K29: 85000 | P29: 24290 | Q29: 236350 | R29: 109290 | S29: 127060 | U29: MAR | V29: 2024
A30: 45383 | F30: 173 | P30: 12110 | Q30: 129060 | R30: 12110 | S30: 116950 | U30: APR | V30: 2024
A31: 45413 | V31: 2024
A32: 45444 | F32: 16 | P32: 1120 | Q32: 11200 | S32: 11200 | V32: 2024
A33: 45474 | V33: 2024
A34: 45505 | V34: 2024
A35: 45536 | V35: 2024
A36: 45566 | V36: 2024
A37: 45597 | V37: 2024
A38: 45627 | V38: 2024
A39: 45658 | V39: 2025
A40: 45689 | V40: 2025
...

Sheet TIME OF PRODUCTION
A5: Row Labels | B5: Sum of Total Qty Produced | C5: Sum of Total Cost | E5: COST per unit = TOTAL COST / TOTAL QTY PRODUCED | L5: PRODUCTION EFFICIENCY = QTY_PRODUCED / TOTAL_COST
A6: 2021 | B6: 1856 | C6: 276125 | G6: =SUM(C6/B6) -> 148.77425 | L6: =GETPIVOTDATA("[Measures].[Sum of Total Qty Produced]",$A$5,"[Range].[ANUALLY]","[Range].[ANUALLY].&[2021]")/GETPIVOTDATA("[Measures].[Sum of Total Cost]",$A$5,"[Range].[ANUALLY]","[Range].[ANUALLY].&[2021]") -> 0.0067215935
A7: DEC | B7: 1856 | C7: 276125 | G7: =SUM(C7/B7) -> 148.77425
A8: 2022 | B8: 18559 | C8: 5092800 | G8: =SUM(C8/B8) -> 274.41134 | L8: =GETPIVOTDATA("[Measures].[Sum of Total Qty Produced]",$A$5,"[Range].[ANUALLY]","[Range].[ANUALLY].&[2022]")/GETPIVOTDATA("[Measures].[Sum of Total Cost]",$A$5,"[Range].[ANUALLY]","[Range].[ANUALLY].&[2022]") -> 0.0036441643
A9: JAN | C9: 63700 | G9: =SUM(C9/B9) -> #DIV/0!
A10: FEB | B10: 2360 | C10: 472150 | G10: =SUM(C10/B10) -> 200.06356
A11: MAR | B11: 788 | C11: 255900 | G11: =SUM(C11/B11) -> 324.74619
A12: APR | B12: 1498 | C12: 340400 | G12: =SUM(C12/B12) -> 227.23632
A13: MAY | B13: 546 | C13: 115800 | G13: =SUM(C13/B13) -> 212.08791
A14: JUN | B14: 645 | C14: 261800 | G14: =SUM(C14/B14) -> 405.89147
A15: JUL | B15: 780 | C15: 142700 | G15: =SUM(C15/B15) -> 182.94872
A16: AUG | B16: 3795 | C16: 1295200 | G16: =SUM(C16/B16) -> 341.29117
A17: SEP | B17: 2286 | C17: 444350 | G17: =SUM(C17/B17) -> 194.37883
A18: OCT | B18: 3774 | C18: 1017500 | G18: =SUM(C18/B18) -> 269.60784
A19: NOV | B19: 430 | C19: 172000 | G19: =SUM(C19/B19) -> 400
A20: DEC | B20: 1657 | C20: 511300 | G20: =SUM(C20/B20) -> 308.5697
A21: 2023 | B21: 17313 | C21: 5566750 | G21: =SUM(C21/B21) -> 321.53584 | L21: =GETPIVOTDATA("[Measures].[Sum of Total Qty Produced]",$A$5,"[Range].[ANUALLY]","[Range].[ANUALLY].&[2023]")/GETPIVOTDATA("[Measures].[Sum of Total Cost]",$A$5,"[Range].[ANUALLY]","[Range].[ANUALLY].&[2023]") -> 0.0031100732
A22: JAN | B22: 824 | C22: 258900 | G22: =SUM(C22/B22) -> 314.19903
A23: MAR | B23: 2011 | C23: 568960 | G23: =SUM(C23/B23) -> 282.92392
A24: APR | B24: 3615 | C24: 877290 | G24: =SUM(C24/B24) -> 242.6805
A25: MAY | B25: 504 | C25: 179420 | G25: =SUM(C25/B25) -> 355.99206
A26: JUN | B26: 760 | C26: 442200 | G26: =SUM(C26/B26) -> 581.84211
A27: JUL | B27: 903 | C27: 360670 | G27: =SUM(C27/B27) -> 399.41307
A28: AUG | B28: 1040 | C28: 275580 | G28: =SUM(C28/B28) -> 264.98077
A29: SEP | B29: 2079 | C29: 690830 | G29: =SUM(C29/B29) -> 332.28956
A30: OCT | B30: 2780 | C30: 971030 | G30: =SUM(C30/B30) -> 349.29137
A31: NOV | B31: 1140 | C31: 295620 | G31: =SUM(C31/B31) -> 259.31579
A32: DEC | B32: 1657 | C32: 646250 | G32: =SUM(C32/B32) -> 390.01207
A33: 2024 | B33: 2010 | C33: 1162000 | G33: =SUM(C33/B33) -> 578.10945 | L33: =GETPIVOTDATA("[Measures].[Sum of Total Qty Produced]",$A$5,"[Range].[ANUALLY]","[Range].[ANUALLY].&[2024]")/GETPIVOTDATA("[Measures].[Sum of Total Cost]",$A$5,"[Range].[ANUALLY]","[Range].[ANUALLY].&[2024]") -> 0.0017297762
A34: JAN | C34: 105400 | G34: =SUM(C34/B34) -> #DIV/0!
A35: FEB | B35: 2010 | C35: 935200 | G35: =SUM(C35/B35) -> 465.27363
A36: MAR | C36: 109290 | G36: =SUM(C36/B36) -> #DIV/0!
A37: APR | C37: 12110 | G37: =SUM(C37/B37) -> #DIV/0!
A38: 2025 | B38: 6141 | C38: 3357300 | G38: =SUM(C38/B38) -> 546.70249 | L38: =GETPIVOTDATA("[Measures].[Sum of Total Qty Produced]",$A$5,"[Range].[ANUALLY]","[Range].[ANUALLY].&[2025]")/GETPIVOTDATA("[Measures].[Sum of Total Cost]",$A$5,"[Range].[ANUALLY]","[Range].[ANUALLY].&[2025]") -> 0.0018291484
A39: MAY | B39: 1526 | C39: 814450 | G39: =SUM(C39/B39) -> 533.7156
A40: JUN | C40: 69375 | G40: =SUM(C40/B40) -> #DIV/0!
A41: JUL | B41: 1656 | C41: 741250 | G41: =SUM(C41/B41) -> 447.61473
A42: AUG | C42: 23550 | G42: =SUM(C42/B42) -> #DIV/0!
A43: SEP | C43: 141250 | G43: =SUM(C43/B43) -> #DIV/0!
A44: OCT | B44: 584 | C44: 273450 | G44: =SUM(C44/B44) -> 468.2363
...

Sheet COST BREAKDOWN OVER TIME
A3: Row Labels | B3: Sum of Total Cost | C3: Sum of Sand Cost | D3: Sum of Cement Cost | E3: Sum of Operators' Payment | F3: Sum of Fuel Cost | G3: Sum of Maintenance | H3: Sum of Delivery Cost
A4: 2021 | B4: 276125 | C4: 90000 | D4: 140000 | E4: 42000 | F4: 4125
A5: 44531 | B5: 276125 | C5: 90000 | D5: 140000 | E5: 42000 | F5: 4125
A6: 2022 | B6: 5092800 | C6: 1857500 | D6: 1608150 | E6: 568400 | F6: 53400 | G6: 90400 | H6: 914950
A7: 44562 | B7: 63700 | H7: 63700
A8: 44593 | B8: 472150 | C8: 147500 | D8: 189000 | E8: 67500 | F8: 4000 | H8: 64150
A9: 44621 | B9: 255900 | C9: 70000 | D9: 119400 | E9: 22400 | F9: 4000 | H9: 40100
A10: 44652 | B10: 340400 | C10: 120000 | D10: 90000 | E10: 48000 | F10: 4400 | H10: 78000
A11: 44682 | B11: 115800 | C11: 40000 | D11: 40000 | E11: 15000 | F11: 2000 | H11: 18800
A12: 44713 | B12: 261800 | C12: 120000 | D12: 82000 | E12: 22500 | F12: 2000 | H12: 35300
A13: 44743 | B13: 142700 | C13: 50000 | D13: 45700 | E13: 15000 | F13: 2000 | H13: 30000
A14: 44774 | B14: 1295200 | C14: 500000 | D14: 348300 | E14: 129000 | F14: 10000 | G14: 77900 | H14: 230000
A15: 44805 | B15: 444350 | C15: 100000 | D15: 214650 | E15: 72000 | F15: 8000 | G15: 2000 | H15: 47700
A16: 44835 | B16: 1017500 | C16: 435000 | D16: 283500 | E16: 112500 | F16: 8000 | G16: 5500 | H16: 173000
A17: 44866 | B17: 172000 | C17: 50000 | D17: 40500 | E17: 15000 | F17: 4000 | G17: 5000 | H17: 57500
A18: 44896 | B18: 511300 | C18: 225000 | D18: 155100 | E18: 49500 | F18: 5000 | H18: 76700
A19: 2023 | B19: 5566750 | C19: 2147500 | D19: 1816750 | E19: 616300 | F19: 86180 | G19: 52700 | H19: 847320
A20: 44927 | B20: 258900 | C20: 87500 | D20: 86400 | E20: 24000 | F20: 4000 | H20: 57000
A21: 44958
A22: 44986 | B22: 568960 | C22: 187500 | D22: 209000 | E22: 66000 | F22: 7500 | G22: 2000 | H22: 96960
A23: 45017 | B23: 877290 | C23: 362500 | D23: 328900 | E23: 120000 | F23: 11030 | G23: 2000 | H23: 52860
A24: 45047 | B24: 179420 | C24: 37500 | D24: 32900 | E24: 9000 | F24: 1500 | H24: 98520
A25: 45078 | B25: 442200 | C25: 212500 | D25: 145500 | E25: 30000 | F25: 2000 | H25: 52200
A26: 45108 | B26: 360670 | C26: 137500 | D26: 135300 | E26: 32000 | F26: 7470 | G26: 20200 | H26: 28200
A27: 45139 | B27: 275580 | C27: 125000 | D27: 87200 | E27: 33500 | F27: 3480 | H27: 26400
A28: 45170 | B28: 690830 | C28: 237500 | D28: 230050 | E28: 74800 | F28: 12800 | G28: 20000 | H28: 115680
A29: 45200 | B29: 971030 | C29: 360000 | D29: 283550 | E29: 138600 | F29: 15600 | G29: 3000 | H29: 170280
A30: 45231 | B30: 295620 | C30: 100000 | D30: 98100 | E30: 32300 | F30: 4800 | G30: 1500 | H30: 58920
A31: 45261 | B31: 646250 | C31: 300000 | D31: 179850 | E31: 56100 | F31: 16000 | G31: 4000 | H31: 90300
A32: 2024 | B32: 1162000 | C32: 400000 | D32: 435800 | E32: 78000 | F32: 10000 | G32: 10000 | H32: 229320
A33: 45292 | B33: 105400 | C33: 45000 | G33: 10000 | H33: 50400
A34: 45323 | B34: 935200 | C34: 270000 | D34: 435800 | E34: 78000 | F34: 10000 | H34: 141400
A35: 45352 | B35: 109290 | C35: 85000 | H35: 24290
A36: 45383 | B36: 12110 | H36: 12110
A37: 45413
A38: 45444 | H38: 1120
A39: 45474
A40: 45505
A41: 45536
A42: 45566
...

Sheet INPUT vs OUTPUT EFFICIENCY
A5: Row Labels | B5: Sum of Total Qty Sold | C5: Sum of Total Qty Produced | D5: Sum of Cement Cost | E5: Sum of Operators' Payment | F5: Sum of Bag Produced | G5: Sum of Tons Of Sand | I5: LABOUR PRODUCTIVITY | J5: SAND EFFICIENCY | K5: CEMENT EFFICIENCY | L5: PRODUCTION vs SALES EFFICIENCY = QTY_SOLD / QTY_PRODUCED %
A6: 2021 | C6: 1856 | D6: 140000 | E6: 42000 | F6: 35 | G6: 30 | I6: =GETPIVOTDATA("Sum of Total Qty Produced",$A$5,"ANUALLY",2021)/GETPIVOTDATA("Sum of Operators' Payment",$A$5,"ANUALLY",2021) -> 0.044190476 | J6: =GETPIVOTDATA("Sum of Total Qty Produced",$A$5,"ANUALLY",2021)/GETPIVOTDATA("Sum of Tons Of Sand ",$A$5,"ANUALLY",2021) -> 61.866667 | K6: =GETPIVOTDATA("Sum of Total Qty Produced",$A$5,"ANUALLY",2021)/GETPIVOTDATA("Sum of Bag Produced",$A$5,"ANUALLY",2021) -> 53.028571 | L6: =B6/C6 -> 0
A7: DEC | C7: 1856 | D7: 140000 | E7: 42000 | F7: 35 | G7: 30
A8: 2022 | B8: 18299 | C8: 18559 | D8: 1608150 | E8: 568400 | F8: 385 | G8: 428 | I8: =GETPIVOTDATA("Sum of Total Qty Produced",$A$5,"ANUALLY",2022)/GETPIVOTDATA("Sum of Operators' Payment",$A$5,"ANUALLY",2022) -> 0.032651302 | J8: =GETPIVOTDATA("Sum of Total Qty Produced",$A$5,"ANUALLY",2022)/GETPIVOTDATA("Sum of Tons Of Sand ",$A$5,"ANUALLY",2022) -> 43.36215 | K8: =C8/GETPIVOTDATA("Sum of Bag Produced",$A$5,"ANUALLY",2022) -> 48.205195 | L8: =B8/C8 -> 0.98599062
A9: JAN | B9: 1274
A10: FEB | B10: 1283 | C10: 2360 | D10: 189000 | E10: 67500 | F10: 45 | G10: 48
A11: MAR | B11: 802 | C11: 788 | D11: 119400 | E11: 22400 | F11: 16 | G11: 20
A12: APR | B12: 1560 | C12: 1498 | D12: 90000 | E12: 48000 | F12: 33 | G12: 30
A13: MAY | B13: 376 | C13: 546 | D13: 40000 | E13: 15000 | F13: 11 | G13: 10
A14: JUN | B14: 706 | C14: 645 | D14: 82000 | E14: 22500 | F14: 15 | G14: 30
A15: JUL | B15: 600 | C15: 780 | D15: 45700 | E15: 15000 | F15: 13 | G15: 10
A16: AUG | B16: 4600 | C16: 3795 | D16: 348300 | E16: 129000 | F16: 86 | G16: 100
A17: SEP | B17: 954 | C17: 2286 | D17: 214650 | E17: 72000 | F17: 48 | G17: 20
A18: OCT | B18: 3460 | C18: 3774 | D18: 283500 | E18: 112500 | F18: 75 | G18: 90
A19: NOV | B19: 1150 | C19: 430 | D19: 40500 | E19: 15000 | F19: 10 | G19: 10
A20: DEC | B20: 1534 | C20: 1657 | D20: 155100 | E20: 49500 | F20: 33 | G20: 60
A21: 2023 | B21: 16622 | C21: 17313 | D21: 1816750 | E21: 616300 | F21: 346 | G21: 412 | I21: =GETPIVOTDATA("Sum of Total Qty Produced",$A$5,"ANUALLY",2023)/GETPIVOTDATA("Sum of Operators' Payment",$A$5,"ANUALLY",2023) -> 0.028091838 | J21: =GETPIVOTDATA("Sum of Total Qty Produced",$A$5,"ANUALLY",2023)/GETPIVOTDATA("Sum of Tons Of Sand ",$A$5,"ANUALLY",2023) -> 42.021845 | K21: =C21/F21 -> 50.037572 | L21: =B21/C21 -> 0.9600878
A22: JAN | B22: 950 | C22: 824 | D22: 86400 | E22: 24000 | F22: 16 | G22: 18
A23: MAR | B23: 1616 | C23: 2011 | D23: 209000 | E23: 66000 | F23: 44 | G23: 38
A24: APR | B24: 3381 | C24: 3615 | D24: 328900 | E24: 120000 | F24: 70 | G24: 72
A25: MAY | B25: 1642 | C25: 504 | D25: 32900 | E25: 9000 | F25: 6 | G25: 8
A26: JUN | B26: 870 | C26: 760 | D26: 145500 | E26: 30000 | F26: 20 | G26: 42
A27: JUL | B27: 470 | C27: 903 | D27: 135300 | E27: 32000 | F27: 21 | G27: 28
A28: AUG | B28: 440 | C28: 1040 | D28: 87200 | E28: 33500 | F28: 21 | G28: 25
A29: SEP | B29: 1928 | C29: 2079 | D29: 230050 | E29: 74800 | F29: 44 | G29: 48
A30: OCT | B30: 2838 | C30: 2780 | D30: 283550 | E30: 138600 | F30: 52 | G30: 65
A31: NOV | B31: 982 | C31: 1140 | D31: 98100 | E31: 32300 | F31: 19 | G31: 18
A32: DEC | B32: 1505 | C32: 1657 | D32: 179850 | E32: 56100 | F32: 33 | G32: 50
A33: 2024 | B33: 3260 | C33: 2010 | D33: 435800 | E33: 78000 | F33: 40 | G33: 63 | I33: =GETPIVOTDATA("Sum of Total Qty Produced",$A$5,"ANUALLY",2024)/GETPIVOTDATA("Sum of Operators' Payment",$A$5,"ANUALLY",2024) -> 0.025769231 | J33: =GETPIVOTDATA("Sum of Total Qty Produced",$A$5,"ANUALLY",2024)/GETPIVOTDATA("Sum of Tons Of Sand ",$A$5,"ANUALLY",2024) -> 31.904762 | K33: =C33/F33 -> 50.25 | L33: =B33/C33 -> 1.6218905
A34: JAN | B34: 720 | G34: 8
A35: FEB | B35: 2020 | C35: 2010 | D35: 435800 | E35: 78000 | F35: 40 | G35: 45
A36: MAR | B36: 347 | G36: 10
A37: APR | B37: 173
A38: 2025 | B38: 5033 | C38: 6141 | D38: 1157100 | E38: 351000 | F38: 110 | G38: 110 | I38: =GETPIVOTDATA("Sum of Total Qty Produced",$A$5,"ANUALLY",2025)/GETPIVOTDATA("Sum of Operators' Payment",$A$5,"ANUALLY",2025) -> 0.017495726 | J38: =GETPIVOTDATA("Sum of Total Qty Produced",$A$5,"ANUALLY",2025)/GETPIVOTDATA("Sum of Tons Of Sand ",$A$5,"ANUALLY",2025) -> 55.827273 | K38: =C38/F38 -> 55.827273 | L38: =B38/C38 -> 0.81957336
A39: MAY | C39: 1526 | D39: 367500 | E39: 87000 | F39: 29 | G39: 10
A40: JUN | B40: 925
A41: JUL | B41: 850 | C41: 1656 | D41: 265500 | E41: 92000 | F41: 29 | G41: 30
A42: AUG | B42: 377
A43: SEP | B43: 550 | G43: 10
A44: OCT | B44: 414 | C44: 584 | D44: 122400 | E44: 30000 | F44: 10
...

Sheet TIME OF SALES
A1: Product Type | B1: (All)
A3: Sum of Qty Sold | B3: Column Labels
A4: Row Labels | B4: MONDAY | C4: TUESDAY | D4: WEDNESDAY | E4: THURSDAY | F4: FRIDAY | G4: SATURDAY | H4: SUNDAY | I4: Grand Total
A5: 2022 | B5: 2186 | C5: 2065 | D5: 1679 | E5: 3672 | F5: 7260 | G5: 1302 | H5: 135 | I5: 18299
A6: JANUARY | B6: 500 | D6: 300 | G6: 474 | I6: 1274
A7: FEBRUARY | B7: 12 | C7: 575 | D7: 400 | E7: 130 | F7: 150 | G7: 16 | I7: 1283
A8: MARCH | B8: 200 | E8: 2 | F8: 500 | G8: 100 | I8: 802
A9: APRIL | E9: 1200 | F9: 200 | G9: 160 | I9: 1560
A10: MAY | B10: 266 | C10: 50 | E10: 60 | I10: 376
A11: JUNE | B11: 80 | C11: 40 | E11: 150 | F11: 400 | G11: 36 | I11: 706
A12: JULY | D12: 100 | G12: 500 | I12: 600
A13: AUGUST | F13: 4600 | I13: 4600
A14: SEPTEMBER | B14: 278 | C14: 50 | D14: 510 | F14: 100 | G14: 16 | I14: 954
A15: OCTOBER | B15: 600 | C15: 1000 | E15: 1280 | F15: 580 | I15: 3460
A16: NOVEMBER | B16: 150 | C16: 250 | D16: 150 | E16: 600 | I16: 1150
A17: DECEMBER | B17: 100 | C17: 100 | D17: 219 | E17: 250 | F17: 730 | H17: 135 | I17: 1534
A18: 2023 | B18: 2882 | C18: 3185 | D18: 5563 | E18: 2043 | F18: 1459 | G18: 1400 | H18: 90 | I18: 16622
A19: JANUARY | B19: 100 | C19: 400 | D19: 400 | E19: 16 | F19: 34 | I19: 950
A20: MARCH | B20: 1016 | D20: 15 | E20: 360 | F20: 225 | I20: 1616
A21: APRIL | B21: 40 | C21: 600 | D21: 2516 | G21: 225 | I21: 3381
A22: MAY | B22: 50 | C22: 715 | D22: 877 | I22: 1642
A23: JUNE | B23: 200 | D23: 100 | E23: 430 | G23: 130 | H23: 10 | I23: 870
A24: JULY | B24: 70 | F24: 200 | G24: 200 | I24: 470
A25: AUGUST | B25: 180 | E25: 180 | H25: 80 | I25: 440
A26: SEPTEMBER | B26: 800 | C26: 320 | F26: 800 | G26: 8 | I26: 1928
A27: OCTOBER | B27: 376 | C27: 900 | D27: 950 | E27: 175 | G27: 437 | I27: 2838
A28: NOVEMBER | B28: 50 | C28: 250 | D28: 100 | E28: 332 | G28: 250 | I28: 982
A29: DECEMBER | D29: 605 | E29: 550 | F29: 200 | G29: 150 | I29: 1505
A30: 2024 | B30: 176 | C30: 350 | D30: 100 | E30: 962 | F30: 1085 | G30: 603 | I30: 3276
A31: JANUARY | B31: 100 | C31: 20 | D31: 100 | E31: 500 | I31: 720
A32: FEBRUARY | B32: 20 | C32: 50 | E32: 450 | F32: 1000 | G32: 500 | I32: 2020
A33: MARCH | C33: 250 | E33: 12 | F33: 85 | I33: 347
A34: APRIL | B34: 40 | C34: 30 | G34: 103 | I34: 173
A35: JUNE | B35: 16 | I35: 16
A36: 2025 | B36: 645 | C36: 266 | D36: 877 | E36: 900 | F36: 529 | G36: 1776 | H36: 40 | I36: 5033
A37: JUNE | B37: 625 | E37: 300 | I37: 925
A38: JULY | E38: 200 | G38: 650 | I38: 850
A39: AUGUST | D39: 38 | E39: 250 | F39: 24 | G39: 25 | H39: 40 | I39: 377
A40: SEPTEMBER | D40: 500 | F40: 50 | I40: 550
A41: OCTOBER | C41: 230 | D41: 14 | E41: 150 | F41: 20 | I41: 414
...

Sheet RATE PER BLOCK TYPES OVERTIME
A1: Product Type | B1: 9 Inches
A3: Row Labels | B3: Average of Rate | F3: YEAR-ON-YEAR GROWTH (YOY) = (CURRENT YEAR - PREVIOUS YEAR) / PREVIOSE YEAR %
A4: 2022 | B4: 360.2381 | F4: 0
A5: JANUARY | B5: 295
A6: FEBRUARY | B6: 300
A7: APRIL | B7: 370
A8: JUNE | B8: 320
A9: AUGUST | B9: 350
A10: SEPTEMBER | B10: 350
A11: OCTOBER | B11: 378.33333
A12: NOVEMBER | B12: 390
A13: DECEMBER | B13: 386.66667
A14: 2023 | B14: 422.79412
A15: JANUARY | B15: 378.33333
A16: MARCH | B16: 402.5
A17: APRIL | B17: 400 | F17: =(GETPIVOTDATA("Rate ",$A$3,"ANUALLY",2023)-GETPIVOTDATA("Rate ",$A$3,"ANUALLY",2022))/GETPIVOTDATA("Rate ",$A$3,"ANUALLY",2022) -> 0.17365188
A18: MAY | B18: 350
A19: JUNE | B19: 390
A20: JULY | B20: 415
A21: AUGUST | B21: 450
A22: SEPTEMBER | B22: 447.5
A23: OCTOBER | B23: 453.33333
A24: NOVEMBER | B24: 500
A25: DECEMBER | B25: 492
A26: 2024 | B26: 645
A27: FEBRUARY | B27: 590
A28: APRIL | B28: 700
A29: JUNE | B29: 700 | F29: =(GETPIVOTDATA("Rate ",$A$3,"ANUALLY",2024)-GETPIVOTDATA("Rate ",$A$3,"ANUALLY",2023))/GETPIVOTDATA("Rate ",$A$3,"ANUALLY",2023) -> 0.52556522
A30: 2025 | B30: 955.55556
A31: JUNE | B31: 1000
A32: JULY | B32: 950
A33: AUGUST | B33: 925
A34: OCTOBER | B34: 975
A35: NOVEMBER | B35: 1000 | F35: =(GETPIVOTDATA("Rate ",$A$3,"ANUALLY",2025)-GETPIVOTDATA("Rate ",$A$3,"ANUALLY",2024))/GETPIVOTDATA("Rate ",$A$3,"ANUALLY",2024) -> 0.48148148
A36: DECEMBER | B36: 925
A37: Grand Total | B37: 487.05882

Sheet CUSTOMER VALUE ANALYSIS 
A1: Product Type | B1: (All)
A3: Row Labels | B3: Sum of Qty Sold | C3: Sum of Rate | D3: Sum of Revenue
A4: ADEBISI SCH. | B4: 200 | C4: 600 | D4: 60000
A5: AHLU SUNNAH | B5: 14 | C5: 800 | D5: 6200
A6: ALHAJA CSTM RFRL 1 | B6: 255 | C6: 1200 | D6: 107500
A7: ALHAJA CSTM RFRL 2 | B7: 40 | C7: 350 | D7: 14000
A8: ALHJ ONAARA | B8: 160 | C8: 730 | D8: 59800
A9: ARISE CSTM | B9: 700 | C9: 340 | D9: 238000
A10: AYO CSTM | B10: 30 | C10: 390 | D10: 11500
A11: BABA ADINI | B11: 16 | C11: 700 | D11: 11200
A12: BABA ASOLO | B12: 792 | C12: 1080 | D12: 283200
A13: BABA IBEJI BRICK-LAYER | B13: 155 | C13: 550 | D13: 45250
A14: BABA OLOKO CSTM | B14: 1050 | C14: 3100 | D14: 727500
A15: BABA SAMSON | B15: 500 | C15: 940 | D15: 145000
... A90: Grand Total | B90: 43167 | C90: 90812 | D90: 18633540

Sheet CUSTOMER CREDIT RISK 
A1: Product Type | B1: (All)
A3: Row Labels | B3: Sum of Amount | C3: Sum of Bad Debt | D3: Sum of Revenue
A4: ADEBISI SCH. | B4: 60000 | D4: 60000
A5: AHLU SUNNAH | B5: 11200 | C5: 5000 | D5: 6200
A6: ALHAJA CSTM RFRL 1 | B6: 108500 | C6: 1000 | D6: 107500
A7: ALHAJA CSTM RFRL 2 | B7: 14000 | D7: 14000
A8: ALHJ ONAARA | B8: 59800 | D8: 59800
A9: ARISE CSTM | B9: 238000 | D9: 238000 | H9: ESTIMATED BAD DEBT RATIO =BAD_DEBT/REVENUE %
A10: Arrangement falling | B10: 20000 | C10: 20000 | D10: 0
A11: AYO CSTM | B11: 11700 | C11: 200 | D11: 11500
A12: BABA ADINI | B12: 11200 | D12: 11200
A13: BABA ASOLO | B13: 283200 | D13: 283200
A14: BABA IBEJI BRICK-LAYER | B14: 45250 | D14: 45250
A15: BABA OLOKO CSTM | B15: 727500 | D15: 727500
A16: BABA SAMSON | B16: 145000 | D16: 145000
A17: BISHOP BRICKLAYER | B17: 221500 | D17: 221500
A18: BRICKLAYER CONERPICE 2 | B18: 2800 | D18: 2800
A19: BRICKLAYER CONERPIEC 1 | B19: 5280 | D19: 5280
A20: BRICKLAYER D.P.R.3 | B20: 240000 | D20: 240000
A21: BRICKLAYER SURVEYOR | B21: 11180 | D21: 11180
A22: BRICKLAYER TELLA | B22: 31500 | D22: 31500
A23: CAPENTER CSTM | B23: 480000 | D23: 480000
... A43: CSTM. WILLY | B43: 143500 | D43: 143500
A44: CSTM@OKO-OPE | B44: 449000 | C44: 6000 | D44: 443000
A45: D.P.R.3 BRICKLAYER | B45: 24600 | C45: 100 | D45: 24500
A46: DAD EMA WELDER CSTM | B46: 74000 | D46: 74000
A47: DAD PRAISE | B47: 60000 | C47: 40000 | D47: 20000
A48: DAD PRAISE REFERRAL 1 | B48: 73300 | C48: 700 | D48: 72600
A49: DAD PRAISE REFERRAL 3 | B49: 751900 | D49: 751900
A50: DAD PRAISE REFERRAL 4 | B50: 154000 | D50: 154000
A51: DAD SALAM BRICKLAYER | B51: 12000 | D51: 12000
A52: DAD SEMILORE | B52: 56000 | D52: 56000
A53: EGBON BIOYE | B53: 150000 | D53: 150000
A54: ELECT. AFEEZ | B54: 489500 | D54: 489500
A55: ENG. LEKAN/BABA | B55: 91200 | D55: 91200
A56: ENG. TUNDE | B56: 237500 | D56: 237500
A57: ENG. WAHEED | B57: 2439100 | C57: 17500 | D57: 2421600
A58: ENG. WAHEED PLUMBER | B58: 522500 | D58: 522500
A59: GBAJUE CSTM | B59: 7030 | C59: 30 | D59: 7000
A60: IJIKU POULTRY CSTM | B60: 140000 | D60: 140000
...

Sheet PROFIT ANALYSIS OVER TIME 
A3: Row Labels | B3: Sum of 6 Inches Qty | C3: Sum of 7 Inches Qty | D3: Sum of 9 Inches Qty | E3: Sum of Total Qty Produced | F3: Sum of Total Revenue | G3: Sum of Total Cost | H3: Sum of Total Profit | J3: Cost vs Profit Relationship
A4: 2021 | B4: 1020 | C4: 500 | D4: 336 | E4: 1856 | G4: 276125 | H4: -276125 | J4: =GETPIVOTDATA("Sum of Total Profit",$A$3,"ANUALLY",2021)/GETPIVOTDATA("Sum of Total Cost",$A$3,"ANUALLY",2021) -> -1
A5: 44531 | B5: 1020 | C5: 500 | D5: 336 | E5: 1856 | G5: 276125 | H5: -276125
A6: 2022 | B6: 6589 | C6: 3442 | D6: 8528 | E6: 18559 | F6: 6068380 | G6: 5092800 | H6: 975580 | J6: =GETPIVOTDATA("Sum of Total Profit",$A$3,"ANUALLY",2022)/GETPIVOTDATA("Sum of Total Cost",$A$3,"ANUALLY",2022) -> 0.19156063
A7: 44562 | F7: 340250 | G7: 63700 | H7: 276550
A8: 44593 | B8: 900 | C8: 1250 | D8: 210 | E8: 2360 | F8: 347950 | G8: 472150 | H8: -124200
A9: 44621 | B9: 440 | C9: 96 | D9: 252 | E9: 788 | F9: 257600 | G9: 255900 | H9: 1700
A10: 44652 | C10: 700 | D10: 798 | E10: 1498 | F10: 521800 | G10: 340400 | H10: 181400
A11: 44682 | C11: 546 | E11: 546 | F11: 114700 | G11: 115800 | H11: -1100
A12: 44713 | D12: 645 | E12: 645 | F12: 222800 | G12: 261800 | H12: -39000
A13: 44743 | B13: 780 | E13: 780 | F13: 190000 | G13: 142700 | H13: 47300
A14: 44774 | B14: 569 | D14: 3226 | E14: 3795 | F14: 1594000 | G14: 1295200 | H14: 298800
A15: 44805 | B15: 1320 | C15: 450 | D15: 516 | E15: 2286 | F15: 297980 | G15: 444350 | H15: -146370
A16: 44835 | B16: 1740 | C16: 400 | D16: 1634 | E16: 3774 | F16: 1176300 | G16: 1017500 | H16: 158800
A17: 44866 | D17: 430 | E17: 430 | F17: 425000 | G17: 172000 | H17: 253000
A18: 44896 | B18: 840 | D18: 817 | E18: 1657 | F18: 580000 | G18: 511300 | H18: 68700
A19: 2023 | B19: 7143 | C19: 2701 | D19: 7469 | E19: 17313 | F19: 6556450 | G19: 5566750 | H19: 989700 | J19: =GETPIVOTDATA("Sum of Total Profit",$A$3,"ANUALLY",2023)/GETPIVOTDATA("Sum of Total Cost",$A$3,"ANUALLY",2023) -> 0.17778776
A20: 44927 | B20: 480 | D20: 344 | E20: 824 | F20: 351320 | G20: 258900 | H20: 92420
A21: 44958
A22: 44986 | B22: 420 | D22: 1591 | E22: 2011 | F22: 644100 | G22: 568960 | H22: 75140
A23: 45017 | B23: 900 | C23: 2500 | D23: 215 | E23: 3615 | F23: 1015940 | G23: 877290 | H23: 138650
A24: 45047 | B24: 303 | C24: 201 | E24: 504 | F24: 584200 | G24: 179420 | H24: 404780
A25: 45078 | D25: 760 | E25: 760 | F25: 343200 | G25: 442200 | H25: -99000
A26: 45108 | D26: 903 | E26: 903 | F26: 181500 | G26: 360670 | H26: -179170
A27: 45139 | B27: 480 | D27: 560 | E27: 1040 | F27: 182200 | G27: 275580 | H27: -93380
A28: 45170 | B28: 660 | D28: 1419 | E28: 2079 | F28: 841200 | G28: 690830 | H28: 150370
A29: 45200 | B29: 1920 | D29: 860 | E29: 2780 | F29: 1255440 | G29: 971030 | H29: 284410
A30: 45231 | B30: 1140 | E30: 1140 | F30: 446900 | G30: 295620 | H30: 151280
A31: 45261 | B31: 840 | D31: 817 | E31: 1657 | F31: 710450 | G31: 646250 | H31: 64200
A32: 2024 | B32: 1560 | C32: 20 | D32: 430 | E32: 2010 | F32: 1790610 | G32: 1162000 | H32: 628610 | J32: =GETPIVOTDATA("Sum of Total Profit",$A$3,"ANUALLY",2024)/GETPIVOTDATA("Sum of Total Cost",$A$3,"ANUALLY",2024) -> 0.54097246
A33: 45292 | F33: 294000 | G33: 105400 | H33: 188600
A34: 45323 | B34: 1560 | C34: 20 | D34: 430 | E34: 2010 | F34: 1120000 | G34: 935200 | H34: 184800
A35: 45352 | F35: 236350 | G35: 109290 | H35: 127060
A36: 45383 | F36: 129060 | G36: 12110 | H36: 116950
A37: 45413
A38: 45444 | F38: 11200 | H38: 11200
A39: 45474
A40: 45505
A41: 45536
A42: 45566
...

Sheet OVERALL_TOTAL
A1: METRIC | B1: VALUE
A2: 6 Inches Qty Produced | B2: =SUM(PRODUCTION_DATA!B2:B50) -> 20598
A3: 7 Inches Qty Produced | B3: =SUM(PRODUCTION_DATA!C2:C50) -> 6663
A4: 9 Inches Qty Produced | B4: =SUM(PRODUCTION_DATA!D2:D50) -> 18618
A5: Total Qty Produced | B5: =SUM(PRODUCTION_DATA!E2:E50) -> 45879
A6: 6 Inches Qty Sold | B6: 18485
A7: 7 Inches Qty Sold | B7: 6620
A8: 9 Inches Qty Sold | B8: 18125
A9: Total Qty Sold | B9: =SUM(PRODUCTION_DATA!F2:F50) -> 43230
A10: Tons Of Sand | B10: =SUM(PRODUCTION_DATA!G2:G50) -> 1043
A11: Bags of Cement | B11: =SUM(PRODUCTION_DATA!H2:H50) -> 925
A12: Bag Produced | B12: =SUM(PRODUCTION_DATA!I2:I50) -> 916
A13: Ltr. Of Fuel | B13: =SUM(PRODUCTION_DATA!J2:J50) -> 690
A14: Total Cost | B14: =SUM(PRODUCTION_DATA!R2:R50) -> 15454975
A15: Total Amount | B15: =SUM(SALES__DATA!F2:F199) -> 18819310
A16: Total Revenue | B16: =SUM(PRODUCTION_DATA!Q2:Q50) -> 18633540
A17: Total Profit | B17: =SUM(PRODUCTION_DATA!S2:S50) -> 3178565
A18: Bad Debt | B18: =SUM(PRODUCTION_DATA!T2:T50) -> 185770
A19: VARIABLE COSTS
A20: Sand Cost | B20: =SUM(PRODUCTION_DATA!K2:K50) -> 5505000
A21: Cement Cost | B21: =SUM(PRODUCTION_DATA!L2:L50) -> 5157800
A22: Fuel Cost | B22: =SUM(PRODUCTION_DATA!N2:N50) -> 238455
A23: FIXED COSTS
A24: Operators' Payment | B24: =SUM(PRODUCTION_DATA!M2:M50) -> 1655700
A25: Maintenance | B25: =SUM(PRODUCTION_DATA!O2:O50) -> 534800
A26: Delivery Cost | B26: =SUM(PRODUCTION_DATA!P2:P50) -> 2364340
A27: RATES
A28: Production_Efficiency | B28: =B9/B5 -> 0.94226117
A29: Profit_Margin | B29: =B17/B16 -> 0.17058299
A30: Bad Debt_Rate | B30: =B18/B15 -> 0.009871244

Sheet KPI_DASHBOARD
A1: METRIC | B1: VALUE
A2: PRODUCTION KPIs
A3: 6 Inches Qty Produced | B3: =SUM(PRODUCTION_DATA!B2:B50) -> 20598
A4: 7 Inches Qty Produced | B4: =SUM(PRODUCTION_DATA!C2:C50) -> 6663
A5: 9 Inches Qty Produced | B5: =SUM(PRODUCTION_DATA!D2:D50) -> 18618
A6: Total Qty Produced | B6: =SUM(PRODUCTION_DATA!E2:E50) -> 45879
A7: Tons Of Sand | B7: =SUM(PRODUCTION_DATA!G2:G50) -> 1043
A8: Bags of Cement | B8: =SUM(PRODUCTION_DATA!H2:H50) -> 925
A9: Bag Produced | B9: =SUM(PRODUCTION_DATA!I2:I50) -> 916
A10: Ltr. Of Fuel | B10: =SUM(PRODUCTION_DATA!J2:J50) -> 690
A11: Production_Efficiency | B11: =B30/B6 -> 0.94226117
A12: Cost per Block | B12: =B19/B6 -> 336.86382
A13: Wastage Ratio% | B13: 0.038
A14: FINANCIAL KPIs
A15: Sand Cost | B15: =SUM(PRODUCTION_DATA!K2:K50) -> 5505000
A16: Cement Cost | B16: =SUM(PRODUCTION_DATA!L2:L50) -> 5157800
A17: Fuel Cost | B17: =SUM(PRODUCTION_DATA!N2:N50) -> 238455
A18: Operators' Payment | B18: =SUM(PRODUCTION_DATA!M2:M50) -> 1655700
A19: Total Cost | B19: =SUM(PRODUCTION_DATA!R2:R50) -> 15454975
A20: Total Amount | B20: =SUM(SALES__DATA!F2:F199) -> 18819310
A21: Total Revenue | B21: =SUM(PRODUCTION_DATA!Q2:Q50) -> 18633540
A22: Total Profit | B22: =SUM(PRODUCTION_DATA!S2:S50) -> 3178565
A23: Bad Debt | B23: =SUM(PRODUCTION_DATA!T2:T50) -> 185770
A24: Profit_Margin% | B24: =B22/B21 -> 0.17058299
A25: Bad Debt_Rate % | B25: =B23/B20 -> 0.009871244
A26: SALES KPIs
A27: 6 Inches Qty Sold | B27: 18485
A28: 7 Inches Qty Sold | B28: 6620
A29: 9 Inches Qty Sold | B29: 18125
A30: Total Qty Sold | B30: =SUM(PRODUCTION_DATA!F2:F50) -> 43230
A31: OPERATIONAL KPIs
A32: Maintenance | B32: =SUM(PRODUCTION_DATA!O2:O50) -> 534800
A33: Delivery Cost | B33: =SUM(PRODUCTION_DATA!P2:P50) -> 2364340

Sheet CHARTS
A3: Row Labels | B3: Sum of Qty Sold | C3: Sum of Revenue
A4: 6 Inches | B4: 18485 | C4: 8289700
A5: 7 Inches | B5: 6620 | C5: 2090500
A6: 9 Inches | B6: 18125 | C6: 8253340
A7: Grand Total | B7: 43230 | C7: 18633540
A9: Product Type | B9: Revenue | C9: PROFIT
A10: 6 Inches | B10: 8289700 | C10: 1357268.5
A11: 7 Inches | B11: 2090500 | C11: 495935.66
A12: 9 Inches | B12: 8253340 | C12: 1325360.8
A18: Row Labels | B18: Sum of Revenue
A19: 2022 | B19: 6068380
A20: 2023 | B20: 6556450
A21: 2024 | B21: 1790610
A22: 2025 | B22: 4218100
A23: Grand Total | B23: 18633540
A25: Year | B25: Total Revenue
A26: 2022 | B26: 6068380
A27: 2023 | B27: 6556450
A28: 2024 | B28: 1790610 | E28: Total Revenue
A29: 2025 | B29: 4218100
E30: 340250
E31: 347950
E32: 257600
E33: 521800
A34: Total Cost | B34: Total Profit | D34: Total Qty Sold | E34: 114700
A35: 276125 | B35: -276125 | E35: 222800
A36: 63700 | B36: 276550 | D36: 1274 | E36: 190000
A37: 472150 | B37: -124200 | D37: 1283 | E37: 1594000
A38: 255900 | B38: 1700 | D38: 802 | E38: 297980
A39: 340400 | B39: 181400 | D39: 1560 | E39: 1176300
A40: 115800 | B40: -1100 | D40: 376 | E40: 425000
A41: 261800 | B41: -39000 | D41: 706 | E41: 580000
A42: 142700 | B42: 47300 | D42: 600 | E42: 351320
A43: 1295200 | B43: 298800 | D43: 4600
A44: 444350 | B44: -146370 | D44: 954 | E44: 644100
A45: 1017500 | B45: 158800 | D45: 3460 | E45: 1015940
A46: 172000 | B46: 253000 | D46: 1150 | E46: 584200
A47: 511300 | B47: 68700 | D47: 1534 | E47: 343200
A48: 258900 | B48: 92420 | D48: 950 | E48: 181500
E49: 182200
...
